2023-05-06 11:33:05 ERROR Traceback (most recent call last):
  File "C:\Users\awlad\AppData\Local\Programs\Python\Python310\lib\site-packages\wandb\cli\cli.py", line 106, in wrapper
    return func(*args, **kwargs)
  File "C:\Users\awlad\AppData\Local\Programs\Python\Python310\lib\site-packages\wandb\cli\cli.py", line 250, in login
    wandb.login(relogin=relogin, key=key, anonymous=anon_mode, host=host, force=True)
  File "C:\Users\awlad\AppData\Local\Programs\Python\Python310\lib\site-packages\wandb\sdk\wandb_login.py", line 77, in login
    configured = _login(**kwargs)
  File "C:\Users\awlad\AppData\Local\Programs\Python\Python310\lib\site-packages\wandb\sdk\wandb_login.py", line 298, in _login
    wlogin.prompt_api_key()
  File "C:\Users\awlad\AppData\Local\Programs\Python\Python310\lib\site-packages\wandb\sdk\wandb_login.py", line 228, in prompt_api_key
    raise UsageError("api_key not configured (no-tty). call " + directive)
wandb.errors.UsageError: api_key not configured (no-tty). call wandb login [your_api_key]

